Workbook

Sheet METAS AMBULATORIAIS 
A1: SANTA CASA DE MISERICÓRDIA DO MARANHÃO CNES 2456959 METAS AMBULATORIAIS 2026
A2: CÓDIGOS | B2: DESCRIÇÃO DOS PROCEDIMENTOS | C2: COMPLEXIDADE | D2: TIPO DE FINANCIAMENTO | E2: META FÍSICA ESTIMADA | G2: TABELA SUS | H2: META FINANCEIRA ESTIMADA
E3: MENSAL | F3: ANUAL | H3: MENSAL | I3: ANUAL
A4: GRUPO 02 PROCEDIMENTOS COM FINALIDADE DIAGNÓSTICA
A5: =UPPER("SUBGRUPO 02 Diagnóstico em laboratório clínico") -> SUBGRUPO 02 DIAGNÓSTICO EM LABORATÓRIO CLÍNICO
A6: 202010120 | B6: DOSAGEM DE ACIDO URICO | C6: MC | D6: MAC | E6: 345 | F6: =E6*12 -> 4140 | G6: 1.85 | H6: =G6*E6 -> 638.25 | I6: =H6*12 -> 7659
A7: 202010180 | B7: DOSAGEM DE AMILASE | C7: MC | D7: MAC | E7: 190 | F7: =E7*12 -> 2280 | G7: 2.25 | H7: =G7*E7 -> 427.5 | I7: =H7*12 -> 5130
A8: 202010201 | B8: DOSAGEM DE BILIRRUBINA TOTAL E FRACOES | C8: MC | D8: MAC | E8: 150 | F8: =E8*12 -> 1800 | G8: 2.01 | H8: =G8*E8 -> 301.5 | I8: =H8*12 -> 3618
A9: 202010210 | B9: DOSAGEM DE CALCIO | C9: MC | D9: MAC | E9: 280 | F9: =E9*12 -> 3360 | G9: 1.85 | H9: =G9*E9 -> 518 | I9: =H9*12 -> 6216
A10: 202010260 | B10: DOSAGEM DE CLORETO | C10: MC | D10: MAC | E10: 25 | F10: =E10*12 -> 300 | G10: 1.85 | H10: =G10*E10 -> 46.25 | I10: =H10*12 -> 555
A11: 202010279 | B11: DOSAGEM DE COLESTEROL HDL | C11: MC | D11: MAC | E11: 800 | F11: =E11*12 -> 9600 | G11: 3.51 | H11: =G11*E11 -> 2808 | I11: =H11*12 -> 33696
A12: 202010287 | B12: DOSAGEM DE COLESTEROL LDL | C12: MC | D12: MAC | E12: 800 | F12: =E12*12 -> 9600 | G12: 3.51 | H12: =G12*E12 -> 2808 | I12: =H12*12 -> 33696
A13: 202010295 | B13: DOSAGEM DE COLESTEROL TOTAL | C13: MC | D13: MAC | E13: 800 | F13: =E13*12 -> 9600 | G13: 1.85 | H13: =G13*E13 -> 1480 | I13: =H13*12 -> 17760
A14: 202010317 | B14: DOSAGEM DE CREATININA | C14: MC | D14: MAC | E14: 700 | F14: =E14*12 -> 8400 | G14: 1.85 | H14: =G14*E14 -> 1295 | I14: =H14*12 -> 15540
A15: 202010325 | B15: DOSAGEM DE CREATINOFOSFOQUINASE (CPK) | C15: MC | D15: MAC | E15: 20 | F15: =E15*12 -> 240 | G15: 3.68 | H15: =G15*E15 -> 73.6 | I15: =H15*12 -> 883.2
A16: 202010384 | B16: DOSAGEM DE FERRITINA | C16: MC | D16: MAC | E16: 290 | F16: =E16*12 -> 3480 | G16: 15.59 | H16: =G16*E16 -> 4521.1 | I16: =H16*12 -> 54253.2
A17: 202010392 | B17: DOSAGEM DE FERRO SERICO | C17: MC | D17: MAC | E17: 230 | F17: =E17*12 -> 2760 | G17: 3.51 | H17: =G17*E17 -> 807.3 | I17: =H17*12 -> 9687.6
... A63: 202120082 | B63: PESQUISA DE FATOR RH (INCLUI D FRACO) | C63: MC | D63: MAC | E63: 53 | F63: =E63*12 -> 636 | G63: 1.37 | H63: =G63*E63 -> 72.61 | I63: =H63*12 -> 871.32
A64: TOTAL SUBGRUPO 02 | E64: =SUM(E6:E63) -> 17382 | F64: =SUM(F6:F63) -> 208584 | H64: =SUM(H6:H63) -> 85165.92 | I64: =SUM(I6:I63) -> 1021991
A67: =UPPER("SUBGRUPO 04 Diagnóstico POR RADIOLOGIA") -> SUBGRUPO 04 DIAGNÓSTICO POR RADIOLOGIA
A68: 204030188 | B68: MAMOGRAFIA BILATERAL PARA RASTREAMENTO | C68: MC | D68: MAC | E68: 300 | F68: =E68*12 -> 3600 | G68: 45 | H68: =G68*E68 -> 13500 | I68: =H68*12 -> 162000
A69: 204060028 | B69: DENSITOMETRIA OSSEA DUOENERGETICA DE COLUNA (VERTEBRAS LOMBARES E/OU FEMUR) | C69: AC | D69: MAC | E69: 400 | F69: =E69*12 -> 4800 | G69: 55.1 | H69: =G69*E69 -> 22040 | I69: =H69*12 -> 264480
A70: TOTAL SUBGRUPO 04 | E70: =SUM(E68:E69) -> 700 | F70: =SUM(F68:F69) -> 8400 | H70: =SUM(H68:H69) -> 35540 | I70: =SUM(I68:I69) -> 426480
A75: =UPPER("SUBGRUPO 05 Diagnóstico por ultrasonografia") -> SUBGRUPO 05 DIAGNÓSTICO POR ULTRASONOGRAFIA
A76: 205010032 | B76: ECOCARDIOGRAFIA TRANSTORACICA | C76: MC | D76: MAC | E76: 40 | F76: =E76*12 -> 480 | G76: 67.86 | H76: =G76*E76 -> 2714.4 | I76: =H76*12 -> 32572.8
A77: TOTAL SUBGRUPO 05 | E77: =SUM(E75:E76) -> 40 | F77: =SUM(F75:F76) -> 480 | H77: =SUM(H75:H76) -> 2714.4 | I77: =SUM(I75:I76) -> 32572.8
A80: =UPPER("SUBGRUPO 06 Diagnóstico por tomografia") -> SUBGRUPO 06 DIAGNÓSTICO POR TOMOGRAFIA
A81: 206010010 | B81: TOMOGRAFIA COMPUTADORIZADA DE COLUNA CERVICAL C/ OU S/ CONTRASTE | C81: AC | D81: MAC | E81: 30 | F81: =E81*12 -> 360 | G81: 86.76 | H81: =G81*E81 -> 2602.8 | I81: =H81*12 -> 31233.6
A82: 206010028 | B82: TOMOGRAFIA COMPUTADORIZADA DE COLUNA LOMBOSACRA C/ OU S/ CONTRASTE | C82: AC | D82: MAC | E82: 130 | F82: =E82*12 -> 1560 | G82: 101.1 | H82: =G82*E82 -> 13143 | I82: =H82*12 -> 157716
A83: 206010036 | B83: TOMOGRAFIA COMPUTADORIZADA DE COLUNA TORACICA C/ OU S/ CONTRASTE | C83: AC | D83: MAC | E83: 35 | F83: =E83*12 -> 420 | G83: 86.76 | H83: =G83*E83 -> 3036.6 | I83: =H83*12 -> 36439.2
A84: 206010044 | B84: TOMOGRAFIA COMPUTADORIZADA DE FACE / SEIOS DA FACE / ARTICULACOES TEMPOROMANDIBULARES | C84: AC | D84: MAC | E84: 27 | F84: =E84*12 -> 324 | G84: 86.75 | H84: =G84*E84 -> 2342.25 | I84: =H84*12 -> 28107
A85: 206010052 | B85: TOMOGRAFIA COMPUTADORIZADA DO PESCOCO | C85: AC | D85: MAC | E85: 20 | F85: =E85*12 -> 240 | G85: 86.75 | H85: =G85*E85 -> 1735 | I85: =H85*12 -> 20820
A86: 206010060 | B86: TOMOGRAFIA COMPUTADORIZADA DE SELA TURCICA | C86: AC | D86: MAC | E86: 10 | F86: =E86*12 -> 120 | G86: 97.44 | H86: =G86*E86 -> 974.4 | I86: =H86*12 -> 11692.8
A87: 206010079 | B87: TOMOGRAFIA COMPUTADORIZADA DO CRANIO | C87: AC | D87: MAC | E87: 118 | F87: =E87*12 -> 1416 | G87: 97.44 | H87: =G87*E87 -> 11497.92 | I87: =H87*12 -> 137975.04
A88: 206020015 | B88: TOMOGRAFIA COMPUTADORIZADA DE ARTICULACOES DE MEMBRO SUPERIOR | C88: AC | D88: MAC | E88: 20 | F88: =E88*12 -> 240 | G88: 86.75 | H88: =G88*E88 -> 1735 | I88: =H88*12 -> 20820
A89: 206020023 | B89: TOMOGRAFIA COMPUTADORIZADA DE SEGMENTOS APENDICULARES (BRACO, ANTEBRAÇO, MÃO, COXA, PERNA, PÉ) | C89: AC | D89: MAC | E89: 7 | F89: =E89*12 -> 84 | G89: 86.75 | H89: =G89*E89 -> 607.25 | I89: =H89*12 -> 7287
A90: 206020031 | B90: TOMOGRAFIA COMPUTADORIZADA DE TORAX | C90: AC | D90: MAC | E90: 30 | F90: =E90*12 -> 360 | G90: 136.41 | H90: =G90*E90 -> 4092.3 | I90: =H90*12 -> 49107.6
A91: 206030010 | B91: TOMOGRAFIA COMPUTADORIZADA DE ABDOMEN SUPERIOR | C91: AC | D91: MAC | E91: 60 | F91: =E91*12 -> 720 | G91: 138.63 | H91: =G91*E91 -> 8317.8 | I91: =H91*12 -> 99813.6
A92: 206030029 | B92: TOMOGRAFIA COMPUTADORIZADA DE ARTICULACOES DE MEMBRO INFERIOR | C92: AC | D92: MAC | E92: 20 | F92: =E92*12 -> 240 | G92: 86.75 | H92: =G92*E92 -> 1735 | I92: =H92*12 -> 20820
A93: 206030037 | B93: TOMOGRAFIA COMPUTADORIZADA DE PELVE / BACIA / ABDOMEN INFERIOR | C93: AC | D93: MAC | E93: 60 | F93: =E93*12 -> 720 | G93: 138.63 | H93: =G93*E93 -> 8317.8 | I93: =H93*12 -> 99813.6
...

Sheet Planilha1
C3: Coluna
C4: ID
C5: Código Procedimento
C6: Procedimento
C7: Grupo
C8: Subgrupo
C9: Complexidade
C10: Tipo Financiamento
C11: Meta Física Mensal
C12: Meta Física Anual
C13: Valor SUS
C14: Meta Financeira Mensal
... C18: Observações

Sheet METAS HOSPITALARES+INTERNAÇÕES
A1: SANTA CASA DE MISERICÓRDIA DO MARANHÃO CNES 2456959 METAS HOSPITALARES 2025
A2: DESCRIÇÃO DOS PROCEDIMENTOS | B2: COMPLEXIDADE | C2: TIPO DE FINANCIAMENTO | D2: META FÍSICA ESTIMADA | F2: CUSTO MÉDIO | G2: META FINANCEIRA ESTIMADA
D3: MENSAL | E3: ANUAL | G3: MENSAL | H3: ANUAL
A4: Cirúrgico
A5: Angioplastia com 1 stent | B5: AC | C5: MAC | D5: 15 | E5: =D5*12 -> 180 | F5: 6397.31 | G5: =F5*D5 -> 95959.65 | H5: =G5*12 -> 1151515.8
A6: Angioplastia com 2 stent | B6: AC | C6: MAC | D6: 15 | E6: =D6*12 -> 180 | F6: 9365.86 | G6: =F6*D6 -> 140487.9 | H6: =G6*12 -> 1685854.8
A7: Angioplastia com balão | B7: AC | C7: MAC | D7: 15 | E7: =D7*12 -> 180 | F7: 5986.83 | G7: =F7*D7 -> 89802.45 | H7: =G7*12 -> 1077629.4
A8: Angioplastia Ambulatorial | B8: AC | C8: MAC | D8: 3 | E8: =D8*12 -> 36 | F8: 2258.09 | G8: =F8*D8 -> 6774.27 | H8: =G8*12 -> 81291.24
A9: TOTAL GERAL METAS HOSPITALARES MAC | D9: =SUM(D5:D8) -> 48 | E9: =SUM(E5:E8) -> 576 | G9: =SUM(G5:G8) -> 333024.27 | H9: =G9*12 -> 3996291.2
A12: DESCRIÇÃO DOS PROCEDIMENTOS | B12: ='METAS HOSPITALARES+INTERNAÇÕES'!A29 -> * Diarias inclusas nos procedimentos | C12: TIPO DE FINANCIAMENTO | D12: META FÍSICA ESTIMADA | F12: CUSTO MÉDIO | G12: META FINANCEIRA ESTIMADA
D13: MENSAL | E13: ANUAL | G13: MENSAL | H13: ANUAL
A14: Internação
A15: Cirurgico | B15: AC | C15: MAC | D15: 273 | E15: =D15*12 -> 3276 | F15: 598.65 | G15: =F15*D15 -> 163431.45 | H15: =G15*12 -> 1961177.4
A16: Obstétrico | B16: AC | C16: MAC | D16: 123 | E16: =D16*12 -> 1476 | F16: 422.82 | G16: =F16*D16 -> 52006.86 | H16: =G16*12 -> 624082.32
A17: Clínico | B17: AC | C17: MAC | D17: 211 | E17: =D17*12 -> 2532 | F17: 1283.53 | G17: =F17*D17 -> 270824.83 | H17: =G17*12 -> 3249898
A18: TOTAL GERAL METAS HOSPITALARES MAC | D18: =SUM(D15:D17) -> 607 | E18: =SUM(E15:E17) -> 7284 | F18: =SUM(F15:F17) -> 2305 | G18: =SUM(G15:G17) -> 486263.14 | H18: =G18*12 -> 5835157.7
A21: DESCRIÇÃO DOS PROCEDIMENTOS | B21: COMPLEXIDADE | C21: TIPO DE FINANCIAMENTO | D21: META FÍSICA ESTIMADA | F21: CUSTO MÉDIO | G21: META FINANCEIRA ESTIMADA
D22: MENSAL | E22: ANUAL | G22: MENSAL | H22: ANUAL
A23: Cirúrgico
A24: Revascularização do Miocardio | B24: AC | C24: FAEC | D24: 2 | E24: 24 | F24: 18571.66 | G24: =D24*F24 -> 37143.32 | H24: =G24*12 -> 445719.84
A25: TOTAL GERAL METAS HOSPITALARES FAEC | D25: 2 | E25: 24 | F25: 18571.66 | G25: =SUM(G20:G24) -> 37143.32 | H25: =G25*12 -> 445719.84
A27: COMPLENTO CIRÚRGICO - REVASCULARIZAÇÃO MIOCARDIO | C27: TESOURO | D27: 2 | E27: 180 | F27: 25114.19 | G27: =F27*D27 -> 50228.38 | H27: =G27*E27 -> 9041108.4
A29: * Diarias inclusas nos procedimentos

Sheet INCENTIVOS 
A1: SANTA CASA DE MISERICÓRDIA DO MARANHÃO CNES 2456959 INCENTIVOS
A3: INCENTIVOS - RECURSOS SUS 2025
A4: Portaria | B4: Tipo Incentivo | C4: Mês | D4: Ano
A5: Portaria GM Nº 719 de 4 de Abril de 2007 | B5: HOSPITAIS FILANTRÓPICOS IAC | C5: 55963.29 | D5: =C5*12 -> 671559.48
A6: Portaria GM Nº 3130 de 24 de Dezembro de 2008 | B6: HOSPITAIS FILANTRÓPICOS IAC | C6: 11192.66 | D6: =C6*12 -> 134311.92
A7: Portaria GM Nº 2506 de 26 de Outubro de 2011 | B7: HOSPITAIS FILANTRÓPICOS IAC | C7: 59116.95 | D7: =C7*12 -> 709403.4
A8: Portaria GM Nº 1416 de 6 de Julho de 2012 | B8: HOSPITAIS FILANTRÓPICOS IAC | C8: 51979.95 | D8: =C8*12 -> 623759.4
A9: Portaria GM Nº 3172 de 28 de dezembro de 2012 | B9: HOSPITAIS FILANTRÓPICOS IAC | C9: 41918.23 | D9: =C9*12 -> 503018.76
A10: Sub Total Hospitais Filantropicos | C10: =SUM(C5:C9) -> 220171.08 | D10: =C10*12 -> 2642053
A11: Portaria GM Nº 719 de 4 de Abril de 2007 | B11: INTEGRASUS | C11: 28828.49 | D11: =C11*12 -> 345941.88
A12: Total dos Incentivos | C12: =SUM(C10:C11) -> 248999.57 | D12: =SUM(D10:D11) -> 2987994.8

Sheet GERAL FISICO 
A1: SANTA CASA DE MISERICÓRDIA DO MARANHÃO CNES 2456959
A2: QUADRO GERAL FISICO NOVO CONVÊNIO
A3: DESCRIÇÃO | B3: MÊS | C3: ANO
A4: METAS AMBULATORIAIS - MC (MAC) | B4: ='METAS AMBULATORIAIS '!E148+'METAS AMBULATORIAIS '!E128+'METAS AMBULATORIAIS '!E127+'METAS AMBULATORIAIS '!E125+'METAS AMBULATORIAIS '!E76+'METAS AMBULATORIAIS '!E68+'METAS AMBULATORIAIS '!E64 -> 21729 | C4: =B4*12 -> 260748
A5: METAS AMBULATORIAIS - AC (MAC) | B5: ='METAS AMBULATORIAIS '!E69+'METAS AMBULATORIAIS '!E94+'METAS AMBULATORIAIS '!E112+'METAS AMBULATORIAIS '!E121+'METAS AMBULATORIAIS '!E126 -> 1712 | C5: =B5*12 -> 20544
A6: Subtotal Ambulatorial | B6: =SUM(B4:B5) -> 23441 | C6: =B6*12 -> 281292
A7: METAS HOSPITALARES - AC (MAC) - Cirúrgico | B7: ='METAS HOSPITALARES+INTERNAÇÕES'!D9 -> 48 | C7: =B7*12 -> 576
A8: METAS HOSPITALARES - MC (MAC) - Internações | B8: ='METAS HOSPITALARES+INTERNAÇÕES'!D18 -> 607 | C8: =B8*12 -> 7284
A9: METAS HOSPITALARES - AC (FAEC) - Cirúrgico | B9: ='METAS HOSPITALARES+INTERNAÇÕES'!D24 -> 2 | C9: =B9*12 -> 24
A10: Subtotal Hospitalar | B10: =B7+B8+B9 -> 657 | C10: =B10*12 -> 7884
A11: Total (Ambulatorial + Hospitalar) | B11: =B6+B10 -> 24098 | C11: =B11*12 -> 289176

Sheet GERAL FINANCEIRO 
A1: SANTA CASA DE MISERICÓRDIA DO MARANHÃO CNES 2456959
A2: QUADRO GERAL FINANCEIRO NOVO CONVÊNIO
A3: DESCRIÇÃO | B3: MÊS | C3: ANO
A4: METAS AMBULATORIAIS - MC (MAC) | B4: ='METAS AMBULATORIAIS '!H64+'METAS AMBULATORIAIS '!H68+'METAS AMBULATORIAIS '!H76+'METAS AMBULATORIAIS '!H125+'METAS AMBULATORIAIS '!H127+'METAS AMBULATORIAIS '!H128+'METAS AMBULATORIAIS '!H148 -> 131286.32 | C4: =B4*12 -> 1575435.8
A5: METAS AMBULATORIAIS - AC (MAC) | B5: ='METAS AMBULATORIAIS '!H69+'METAS AMBULATORIAIS '!H94+'METAS AMBULATORIAIS '!H112+'METAS AMBULATORIAIS '!H121+'METAS AMBULATORIAIS '!H126 -> 324859.62 | C5: =B5*12 -> 3898315.4
A6: Subtotal Ambulatorial | B6: =SUM(B4:B5) -> 456145.94 | C6: =B6*12 -> 5473751.3
A7: METAS HOSPITALARES - AC (MAC) - Cirúrgico | B7: ='METAS HOSPITALARES+INTERNAÇÕES'!G9 -> 333024.27 | C7: =B7*12 -> 3996291.2
A8: METAS HOSPITALARES - AC (FAEC) - Cirúrgico | B8: ='METAS HOSPITALARES+INTERNAÇÕES'!G25 -> 37143.32 | C8: =B8*12 -> 445719.84
A9: METAS HOSPITALARES - MC (MAC) - Internação | B9: ='METAS HOSPITALARES+INTERNAÇÕES'!G18 -> 486263.14 | C9: =B9*12 -> 5835157.7
A10: Total (Ambulatorial + Hospitalar) | B10: =SUM(B7:B9) -> 856430.73 | C10: =B10*12 -> 10277169
A11: INCENTIVOS IAC + INTEGRASUS | B11: ='INCENTIVOS '!C12 -> 248999.57 | C11: =B11*12 -> 2987994.8
A12: Total Geral Incentivos | B12: =B11 -> 248999.57 | C12: =B12*12 -> 2987994.8
A13: RECURSO TESOURO METAS AMBULATORIAIS | B13: ='METAS AMBULATORIAIS '!H96+'METAS AMBULATORIAIS '!H114+'METAS AMBULATORIAIS '!H132 -> 151496 | C13: =B13*12 -> 1817952
A14: RECURSO TESOURO METAS HOSPITALARES | B14: ='METAS HOSPITALARES+INTERNAÇÕES'!G27 -> 50228.38 | C14: =B14*12 -> 602740.56
A15: Total Recurso Tesouro | B15: =SUM(B13:B14) -> 201724.38 | C15: =SUM(C13:C14) -> 2420692.6
A16: TOTAL GERAL | B16: =B6+B10+B12+B15 -> 1763300.6 | C16: =B16*12 -> 21159607
A19: OBS: Os recursos do Tesouro correspondem ao acréscimo necessário para a cobertura do uso de contraste em exames, considerando que aproximadamente 30% dos exames de imagem demandam a sua utilização. O recurso também contemplará os procedimentos cirúrgicos de revascularização. Destaca-se que é necessário o incremento com recurso do Tesouro para custear tanto a utilização do contraste quanto a realização dos procedimentos cirúrgicos de revascularização.

Sheet INDICADORES DE QUALIDADE 
A1: SANTA CASA DE MISERICÓRDIA DO MARANHÃO CNES 2456959 INDICADORES DE QUALIDADE
B2: Indicador | C2: Responsável | D2: Objetivo | E2: Fórmula | F2: Meta | G2: Evidências para envio à CAC | H2: Pontuação mês
A3: 1 | B3: Produção laboratorial - Global | C3: Laboratório + setor Financeiro | D3: Monitorar o volume total de exames laboratoriais realizados, garantindo coerência entre a demanda assistencial, capacidade instalada e contratualização. | E3: Total de exames laboratoriais realizados no mês | F3: Manter tendência estável ou crescente conforme demanda assistencial e pactuação contratual, com variação ≤ 10% ao mês. | G3: Relatório de Produção SADT (BPA/SAI/SIH-SUS) + VIVER | H3: 10
E4: Considera-se a soma de todos os procedimentos laboratoriais registrados no BPA/SIA-SUS.
A5: 2 | B5: Produção SADT - Global | C5: SADT + setor Financeiro | D5: Monitorar o volume de procedimentos diagnósticos e terapêuticos realizados no período, assegurando cobertura assistencial e planejamento de fila. | E5: Total de procedimentos/exames SADT realizados no mês | F5: Manter produção compatível com planejamento assistencial e contratualização, com variabilidade controlada (≤ 10% mês/mês). | G5: Relatório de Produção SADT (BPA/SAI/SIH-SUS) + VIVER | H5: 10
E6: Inclui todos os procedimentos registrados no BPA/SIA-SUS provenientes de serviços de diagnóstico e terapêutica.
A7: 3 | B7: Produção ambulatorial - Global | C7: Coordenação Ambulatorial + setor Financeiro | D7: Acompanhar a produção ambulatorial total, garantindo acesso regulado, continuidade do cuidado e equilíbrio entre oferta e demanda. | E7: Total de consultas/atendimentos ambulatoriais realizados no mês. | F7: Manter volume conforme pactuação e carteira de serviços, com acompanhamento de tendência mensal. | G7: Relatórios de Produção Ambulatorial (BPA/SIA-SUS) + VIVER | H7: 10
E8: Soma dos atendimentos ambulatoriais consolidados no BPA e exportados pelo SIA-SUS.
A9: 4 | B9: Regulação de Leitos | C9: NIR / Coordenação de Leitos | D9: Garantir alocação eficiente de leitos entre a solicitação e a resposta. | E9: Tempo médio (horas) | F9: < 2horas | G9: Relatórios + VIVER | H9: 10
A11: 5 | B11: Taxa de Ocupação de Leitos GLOBAL | C11: NIR | D11: Garantir uso adequado da capacidade instalada. | E11: Pacientes-dia / leitos-dia × 100 | F11: 80% a 90% | G11: Relatórios NIR+ VIVER | H11: 10
A17: 6 | B17: Taxas de ocupação de leitos por SETOR | C17: NIR | D17: Garantir uso adequado da capacidade instalada, evitando superlotação ou subutilização dos leitos. | E17: Pacientes-dia do setor / leitos-dia do setor × 100 | F17: 80% a 90% | G17: Relatórios NIR+ VIVER | H17: 10
A18: 7 | B18: Tempo Médio de Permanência dos pacientes -Global | C18: NIR | D18: Avaliar eficiência do cuidado e gestão de leitos em toda a instituição. | E18: (Dias de internação acumulados ÷ Nº de altas no período) | F18: ≤ 7 dias | G18: Relatórios NIR+ VIVER | H18: 10
A20: 8 | B20: Tempo Médio de Permanência dos pacientes -Setorizado | C20: NIR | D20: Identificar setores com permanência acima ou abaixo do esperado, orientando intervenções específicas. | E20: (Dias de internação no setor ÷ Nº de altas do setor) | F20: Clínica Médica: 6–9 dias | G20: Relatórios NIR+ VIVER | H20: 10
F21: Cirúrgica: 3–6 dias
F22: UTI: 7–14 dias
F23: Prolongados ≤ 22 dias
A24: 9 | B24: Atualização Continua do CNES | C24: Direção | D24: Garantir que o registro do CNES reflita coerência entre capacidade instalada, serviços habilitados e contratualização. | E24: (Atualizações realizadas ÷ Atualizações necessárias) × 100 | F24: 100% das atualizações mantidas em conformidade contínua. | G24: Sistema CNES / VIVER / Relatórios da Direção Administrativa + visita técnica | H24: 10
A25: 10 | B25: Taxa de Mortalidade Institucional (>24h) | C25: Direção Clínica / NSP | D25: Monitorar mortalidade institucional e causas evitáveis. | E25: Óbitos >24h / saídas × 100 | F25: Conforme perfil e risco ajustado | G25: SIM + Relatório | H25: 10
A32: 11 | B32: Taxa de Readmissão ≤ 30 dias | C32: NIR + NSP | D32: Reduzir readmissões hospitalares evitáveis, relacionadas a falhas na alta, plano terapêutico ou continuidade do cuidado na rede. | E32: Readmissões ≤ 30 dias / Total de Altas no período × 100 | F32: ≤ 3% | G32: Relatório + VIVER | H32: 10
A33: NOTA: Consideram-se metas não alcançadas aquelas que obtiverem pontuação inferior a 10 (dez) na avaliação mensal do indicador. Nesses casos, será atribuída nota 5 (cinco) para efeito de somatório da pontuação global.
